-Probably in urllib3
Exception in thread Thread-88:
Traceback (most recent call last):
  File "/usr/lib/python2.6/threading.py", line 525, in __bootstrap_inner
    self.run()
  File "/home/daniel/media/code/tcrawler/lib/threads.py", line 37, in run
    resp_item = self.agent.fetch(qitem)
  File "/home/daniel/media/code/tcrawler/lib/agent.py", line 80, in fetch
    return self.fetch(qitem)
  File "/home/daniel/media/code/tcrawler/lib/agent.py", line 66, in fetch
    resp = pool.get_url(qitem.url, retries=self.max_retry, redirect=False)
  File "/usr/local/lib/python2.6/dist-packages/urllib3-0.3-py2.6.egg/urllib3/connectionpool.py", line 231, in get_url
    return self.urlopen('GET', url, headers=headers, retries=retries, redirect=redirect)
  File "/usr/local/lib/python2.6/dist-packages/urllib3-0.3-py2.6.egg/urllib3/connectionpool.py", line 190, in urlopen
    conn = self._get_conn()
  File "/usr/local/lib/python2.6/dist-packages/urllib3-0.3-py2.6.egg/urllib3/connectionpool.py", line 137, in _get_conn
    return conn or self._new_conn()
  File "/usr/local/lib/python2.6/dist-packages/urllib3-0.3-py2.6.egg/urllib3/connectionpool.py", line 124, in _new_conn
    return HTTPConnection(host=self.host, port=self.port)
  File "/usr/lib/python2.6/httplib.py", line 656, in __init__
    self._set_hostport(host, port)
  File "/usr/lib/python2.6/httplib.py", line 667, in _set_hostport
    i = host.rfind(':')
AttributeError: 'NoneType' object has no attribute 'rfind'

Traceback (most recent call last):
  File "/usr/lib/python2.6/threading.py", line 525, in __bootstrap_inner
    self.run()
  File "/home/daniel/media/code/tcrawler/lib/threads.py", line 37, in run
    resp_item = self.agent.fetch(qitem)
  File "/home/daniel/media/code/tcrawler/lib/agent.py", line 80, in fetch
    return self.fetch(qitem)
  File "/home/daniel/media/code/tcrawler/lib/agent.py", line 80, in fetch
    return self.fetch(qitem)
  File "/home/daniel/media/code/tcrawler/lib/agent.py", line 58, in fetch
    port = url_parts.port or None
  File "/usr/lib/python2.6/urlparse.py", line 81, in port
    return int(port, 10)
ValueError: invalid literal for int() with base 10: ''


Exception in thread Thread-75:
Traceback (most recent call last):
  File "/usr/lib/python2.6/threading.py", line 525, in __bootstrap_inner
    self.run()
  File "/home/daniel/media/code/tcrawler/lib/threads.py", line 37, in run
    resp_item = self.agent.fetch(qitem)
  File "/home/daniel/media/code/tcrawler/lib/agent.py", line 65, in fetch
    resp = urllib2.urlopen(qitem.url, timeout=self.http_timeout)
  File "/usr/lib/python2.6/urllib2.py", line 124, in urlopen
    return _opener.open(url, data, timeout)
  File "/usr/lib/python2.6/urllib2.py", line 389, in open
    response = self._open(req, data)
  File "/usr/lib/python2.6/urllib2.py", line 407, in _open
    '_open', req)
  File "/usr/lib/python2.6/urllib2.py", line 367, in _call_chain
    result = func(*args)
  File "/usr/lib/python2.6/urllib2.py", line 1146, in http_open
    return self.do_open(httplib.HTTPConnection, req)
  File "/usr/lib/python2.6/urllib2.py", line 1119, in do_open
    r = h.getresponse()
  File "/usr/lib/python2.6/httplib.py", line 974, in getresponse
    response.begin()
  File "/usr/lib/python2.6/httplib.py", line 391, in begin
    version, status, reason = self._read_status()
  File "/usr/lib/python2.6/httplib.py", line 355, in _read_status
    raise BadStatusLine(line)
BadStatusLine

BUG #100
Happens when the connection times out, since content is none  Should retry.

Traceback (most recent call last):
  File "/home/daniel/media/code/JobSite/projects/crawler/lib/threads.py", line 75, in run
    new_work_units = work_unit.command.execute(work_unit)
  File "/home/daniel/media/code/JobSite/projects/crawler/lib/commands/base.py", line 90, in execute
    self.get_soup_content(resp.content),
  File "/home/daniel/media/code/JobSite/projects/crawler/lib/commands/base.py", line 192, in get_soup_content
    matches = self.stop_regex.search(content)
TypeError: expected string or buffer

